<?xml version="1.0" encoding="UTF-8"?>
<!-- Generated by org.testng.reporters.JUnitReportReporter -->
<testsuite hostname="DESKTOP-LM8VLMM" failures="1" tests="3" name="com.qa.testNG.Class2" time="5.369" errors="0" timestamp="2023-12-17T13:25:59 EST" skipped="0">
  <testcase classname="com.qa.testNG.Class2" name="validateLogin" time="1.364">
    <failure message="The following asserts failed:
	Invalid credentials &gt;&gt;  expected [Paul CollingsH] but found [Paul Collings]" type="java.lang.AssertionError">
      <![CDATA[java.lang.AssertionError: The following asserts failed:
Invalid credentials >>  expected [Paul CollingsH] but found [Paul Collings]
at org.testng.asserts.SoftAssert.assertAll(SoftAssert.java:46)
at org.testng.asserts.SoftAssert.assertAll(SoftAssert.java:30)
at com.qa.testNG.Class2.validateLogin(Class2.java:40)
at java.base/jdk.internal.reflect.NativeMethodAccessorImpl.invoke0(Native Method)
at java.base/jdk.internal.reflect.NativeMethodAccessorImpl.invoke(NativeMethodAccessorImpl.java:77)
at java.base/jdk.internal.reflect.DelegatingMethodAccessorImpl.invoke(DelegatingMethodAccessorImpl.java:43)
at java.base/java.lang.reflect.Method.invoke(Method.java:568)
at org.testng.internal.invokers.MethodInvocationHelper.invokeMethod(MethodInvocationHelper.java:136)
at org.testng.internal.invokers.TestInvoker.invokeMethod(TestInvoker.java:658)
at org.testng.internal.invokers.TestInvoker.invokeTestMethod(TestInvoker.java:219)
at org.testng.internal.invokers.MethodRunner.runInSequence(MethodRunner.java:50)
at org.testng.internal.invokers.TestInvoker$MethodInvocationAgent.invoke(TestInvoker.java:923)
at org.testng.internal.invokers.TestInvoker.invokeTestMethods(TestInvoker.java:192)
at org.testng.internal.invokers.TestMethodWorker.invokeTestMethods(TestMethodWorker.java:146)
at org.testng.internal.invokers.TestMethodWorker.run(TestMethodWorker.java:128)
at java.base/java.util.ArrayList.forEach(ArrayList.java:1511)
at org.testng.TestRunner.privateRun(TestRunner.java:808)
at org.testng.TestRunner.run(TestRunner.java:603)
at org.testng.SuiteRunner.runTest(SuiteRunner.java:429)
at org.testng.SuiteRunner.runSequentially(SuiteRunner.java:423)
at org.testng.SuiteRunner.privateRun(SuiteRunner.java:383)
at org.testng.SuiteRunner.run(SuiteRunner.java:326)
at org.testng.SuiteRunnerWorker.runSuite(SuiteRunnerWorker.java:52)
at org.testng.SuiteRunnerWorker.run(SuiteRunnerWorker.java:95)
at org.testng.TestNG.runSuitesSequentially(TestNG.java:1249)
at org.testng.TestNG.runSuitesLocally(TestNG.java:1169)
at org.testng.TestNG.runSuites(TestNG.java:1092)
at org.testng.TestNG.run(TestNG.java:1060)
at org.testng.remote.AbstractRemoteTestNG.run(AbstractRemoteTestNG.java:115)
at org.testng.remote.RemoteTestNG.initAndRun(RemoteTestNG.java:251)
at org.testng.remote.RemoteTestNG.main(RemoteTestNG.java:77)
]]>
    </failure>
  </testcase> <!-- validateLogin -->
  <system-out/>
  <testcase classname="com.qa.testNG.Class2" name="launchApplication" time="3.514"/>
  <system-out/>
  <testcase classname="com.qa.testNG.Class2" name="loginTotheApplication" time="0.491"/>
  <system-out/>
</testsuite> <!-- com.qa.testNG.Class2 -->
